Traceback (most recent call last):
  File "/home/kms6743/anaconda3/envs/comb/lib/python3.7/site-packages/pandas/core/indexes/base.py", line 3080, in get_loc
    return self._engine.get_loc(casted_key)
  File "pandas/_libs/index.pyx", line 70, in pandas._libs.index.IndexEngine.get_loc
  File "pandas/_libs/index.pyx", line 101, in pandas._libs.index.IndexEngine.get_loc
  File "pandas/_libs/hashtable_class_helper.pxi", line 4554, in pandas._libs.hashtable.PyObjectHashTable.get_item
  File "pandas/_libs/hashtable_class_helper.pxi", line 4562, in pandas._libs.hashtable.PyObjectHashTable.get_item
KeyError: 'Predicted Structure (smiles)'

The above exception was the direct cause of the following exception:

Traceback (most recent call last):
  File "ecoli_metfilter.py", line 469, in <module>
    rt_important_features=rt_important_features
  File "/home/kms6743/Documents/MINE-Database/minedatabase/filters/metabolomics.py", line 121, in __init__
    smiles = row["Predicted Structure (smiles)"]
  File "/home/kms6743/anaconda3/envs/comb/lib/python3.7/site-packages/pandas/core/series.py", line 853, in __getitem__
    return self._get_value(key)
  File "/home/kms6743/anaconda3/envs/comb/lib/python3.7/site-packages/pandas/core/series.py", line 961, in _get_value
    loc = self.index.get_loc(label)
  File "/home/kms6743/anaconda3/envs/comb/lib/python3.7/site-packages/pandas/core/indexes/base.py", line 3082, in get_loc
    raise KeyError(key) from err
KeyError: 'Predicted Structure (smiles)'
